Workbook

Sheet lặt vặt
A1: KHẢO SÁT DỊCH VỤ
A3: STT | B3: Dịch vụ | C3: NCC | D3: Liên hệ | E3: Chi phí | F3: Source
A4: 1 | B4: Media | C4: Thợ Chã village | E4: - 1 thợ chụp: 1tr5 - Video recap: 2tr5 - Video full: 2 tr | F4: Ánh MKT
B5: Xe Cao Bằng - Hạ Long
B6: Ăn trưa ngày 5/10 | C6: Nhà hàng Thăng Long
A7: 2 | B7: Khách sạn | C7: New star | D7: Ms. Linh sales 093 688 03 86 | F7: Chị Hương push từ chủ đầu tư
B8: Nhà hàng | C8: Thiên Anh | F8: Quyên (fm chị Hương)
B9: Nhà hàng | C9: Thăng Long
B10: Tàu 99 chỗ | C10: Aurora | F10: - 910k/khách (đã Vat) phụ thu 35 slot trống 200k/slot
B11: Tàu 99 chỗ | C11: Phương án 1 | F11: Tàu đi tuyến 1. 3h-3,5h. Tiền tàu: 6.500.000 Vé 330.000/ người
C12: Phương án 2 | F12: Tàu tuyến 2 5,5-6h Ghép: 750k/khách Thuê riêng: 800k/khách Bao gồm: tàu, vé vịnh, ăn buffet trưa Không bao gồm kayak hang luồn | G12: Nếu cắt Titop thì về sớm khoảng 30 phút
B13: Make up | C13: Lã Thu Uyên makeup | D13: 0𝟵𝟲𝟮𝟲𝟳𝟳𝟮𝟵𝟴
B14: Ăn tối ngày 6/10 tại Lạng Sơn | C14: Nhà hàng The Pride | D14: 0869661689 Lễ tân
B16: Số lượng makeup và làm tóc để báo thợ
C17: Make + tóc | D17: tóc lẻ
B18: Cao Bằng
B19: Quảng Ninh | C19: Quyên | D19: Ngân, Trà
B24: Chị Nga bếp mua
B25: Ngày 5/10/2026
B26: 11h đoàn CB vào văn phòng
B28: Mua hoa quả tiếp đoàn: 35 người:
B29: 2 quả dưa hấu
B30: Ổi 5kg
B32: Tàu 6/10/2026 (4 tiếng)
B33: Mực khô + tương ớt(nếu còn)
B34: Hồng giòn, củ đậu, dao 2 con
B35: Giấy ăn khô
B36: Túi bóng
B37: Găng tay nilon
B38: Hạt hướng dương

Sheet Chương trình
A1: LỊCH TRÌNH CHƯƠNG TRÌNH DU LỊCH CAO BẰNG - HẠ LONG
A4: Ngày | B4: Thời gian | C4: Hoạt động
A5: 46300 | B5: 04h00 | C5: Xe đón đoàn từ Tà Lùng - Thành phố Cao Bằng - Quảng Ninh
B6: 07h00 | C6: Ăn sáng tại Lạng Sơn
B7: 11h00 | C7: Đoàn tới Quảng Ninh, ghé thăm Văn phòng đại diện công ty
B8: 11h30 | C8: Đoàn di chuyển ra ăn trưa tại nhà hàng Thiên Anh
B9: 14h00 | C9: Đoàn Cao Bằng nhận phòng khách sạn New Star Halong hotel
B10: 15h00 | C10: Nghỉ ngơi, vui chơi tự do
B11: 18h00 | C11: Băt đầu Gala tại Trung tâm tổ chức sự kiện Thăng Long
B12: 21h00 | C12: Kết thúc Gala, đoàn vui chơi tự do, khám phá Hạ Long về đêm
A14: 46301 | B14: 07h00 | C14: Ăn sáng tại khách sạn
B15: 07h30 | C15: Xe đón đoàn ra cảng tàu khách quốc tế Hạ Long. Khách lên tàu thăm quan vịnh Hạ Long
B16: 08h00 | C16: Tàu xuất bến. Du khách ngắm cảnh và sử dụng dịch vụ trên tàu. Trong hành trình, khách sẽ thăm quan động Thiên Cung và hang Đầu Gỗ
B17: 12h00 | C17: Tàu cập bến. Xe đón đoàn di chuyển đến nhà hàng Thiên Tân ăn trưa
B18: 14h00 | C18: Khách lên xe về Cao Bằng. Đoàn Quảng Ninh và Cao Bằng chia tay
B19: 18h00 | C19: Đoàn Cao Bằng dừng chân ăn tối tại Lạng Sơn
B20: 23h00 | C20: Đoàn về lại Tà Lùng và thành phố Cao Bằng. Kết thúc hành trình

Sheet Danh sách MASTER
A1: DANH SÁCH NHÂN VIÊN THAM DỰ CHƯƠNG TRÌNH KỶ NIỆM 1 NĂM RA MẮT THƯƠNG HIỆU TÀ LÙNG QUANG MINH 2026
N2: Sáng 05/10/2026 | O2: Ngày 05/10/2026 | P2: Tối ngày 05/10/2026 | Q2: Sáng ngày 06/10/2026 | R2: Trưa ngày 06/10/2026 | S2: Tối ngày 06/10/2026
A3: STT | B3: Mã nhân viên | C3: Họ và tên | D3: Phòng ban | E3: Bộ phận | F3: Vị trí | G3: Đối tượng | H3: Giới tính | I3: Di chuyển từ | J3: Tham dự chương trình du lịch | K3: Thuê xe Cao Bằng - Quảng Ninh | L3: Ghi chú đi cùng xe ai (nếu ko đi xe to cùng đoàn) | M3: Khách sạn | N3: Ăn sáng trên đường đi (NV Cao Bằng) | O3: Ăn trưa nhà hàng | P3: Dự tiệc Gala | Q3: Đi thuyền thăm vịnh Hạ Long | R3: Ăn trưa | S3: Ăn tối (NV Cao Bằng) | T3: Lý do không tham gia | U3: Ghi chú | V3: Công ty | W3: Công ty xuất hoá đơn
A4: 1 | B4: 005 | C4: Vũ Việt Tùng | D4: Ban Tổng Giám đốc | E4: Quản lý chung | F4: Phó Tổng Giám đốc | G4: Nhân viên | H4: Nam | I4: Cao Bằng | J4: 1 | K4: 1 | N4: 1 | O4: 1 | P4: 1 | Q4: =if(J4=1,1,"") -> 1 | R4: =Q4 -> 1 | S4: =N4 -> 1 | V4: Phú Anh | W4: Phú Anh
A5: =A4+1 -> 2 | B5: 087 | C5: Đinh Thị Bờ | D5: Hành chính - Nhân sự | E5: Hành chính | F5: Nhân viên bếp | G5: Nhân viên | H5: Nữ | I5: Cao Bằng | J5: 1 | K5: =if(and(I5="Cao Bằng",J5=1),1,"") -> 1 | M5: 1 | N5: =if(and(I5="Cao Bằng",J5=1),1,"") -> 1 | O5: =if(J5=1,1,"") -> 1 | P5: =if(J5=1,1,"") -> 1 | Q5: =if(J5=1,1,"") -> 1 | R5: =Q5 -> 1 | S5: =N5 -> 1 | V5: Sơn Cảng | W5: Sơn Cảng
A6: =A5+1 -> 3 | B6: 069 | C6: Đinh Văn Thảo | D6: Hành chính - Nhân sự | E6: Hành chính | F6: Nhân viên Lái xe | G6: Nhân viên | H6: Nam | I6: Cao Bằng | J6: 1 | L6: Đi cùng anh Lợi | P6: =if(J6=1,1,"") -> 1 | Q6: =if(J6=1,1,"") -> 1 | R6: 1 | V6: Sơn Cảng | W6: Sơn Cảng
A7: =A6+1 -> 4 | B7: 037 | C7: Phạm Thị Hằng | D7: Hành chính - Nhân sự | E7: Hành chính | F7: Nhân viên tạp vụ | G7: Nhân viên | H7: Nữ | I7: Cao Bằng | J7: 1 | K7: =if(and(I7="Cao Bằng",J7=1),1,"") -> 1 | M7: 1 | N7: =if(and(I7="Cao Bằng",J7=1),1,"") -> 1 | O7: =if(J7=1,1,"") -> 1 | P7: =if(J7=1,1,"") -> 1 | Q7: =if(J7=1,1,"") -> 1 | R7: =Q7 -> 1 | S7: =N7 -> 1 | V7: Phú Anh | W7: Phú Anh
A8: =A7+1 -> 5 | B8: 068 | C8: Hà Thị Hòa | D8: Hành chính - Nhân sự | E8: Hành chính | F8: Nhân viên tạp vụ | G8: Nhân viên | H8: Nữ | I8: Cao Bằng | J8: 1 | K8: =if(and(I8="Cao Bằng",J8=1),1,"") -> 1 | M8: 1 | N8: =if(and(I8="Cao Bằng",J8=1),1,"") -> 1 | O8: =if(J8=1,1,"") -> 1 | P8: =if(J8=1,1,"") -> 1 | Q8: =if(J8=1,1,"") -> 1 | R8: =Q8 -> 1 | S8: =N8 -> 1 | V8: Sơn Cảng | W8: Sơn Cảng
A9: =A8+1 -> 6 | B9: 016 | C9: Bế Ngọc Dung | D9: Hành chính - Nhân sự | E9: Hành chính - Nhân sự | F9: Nhân viên Hành chính - Nhân sự | G9: Nhân viên | H9: Nữ | I9: Cao Bằng | J9: 1 | K9: =if(and(I9="Cao Bằng",J9=1),1,"") -> 1 | M9: 1 | N9: =if(and(I9="Cao Bằng",J9=1),1,"") -> 1 | O9: =if(J9=1,1,"") -> 1 | P9: =if(J9=1,1,"") -> 1 | Q9: =if(J9=1,1,"") -> 1 | R9: =Q9 -> 1 | S9: =N9 -> 1 | V9: Phú Anh | W9: Phú Anh
A10: =A9+1 -> 7 | B10: 138 | C10: Hà Huy Hùng | D10: Kế hoạch - Dự án | E10: Ban Quản lý dự án | F10: Kỹ sư cơ điện | G10: Nhân viên | H10: Nam | I10: Cao Bằng | K10: =if(and(I10="Cao Bằng",J10=1),1,"") | N10: =if(and(I10="Cao Bằng",J10=1),1,"") | O10: =if(J10=1,1,"") | P10: =if(J10=1,1,"") | Q10: =if(J10=1,1,"") | R10: =Q10 | S10: =N10 | T10: trùng lịch học | V10: Sơn Cảng | W10: Sơn Cảng
A11: =A10+1 -> 8 | B11: 066 | C11: Nguyễn Quang Đạt | D11: Kế hoạch - Dự án | E11: Ban Quản lý dự án | F11: Trưởng ban Quản lý dự án | G11: Nhân viên | H11: Nam | I11: Cao Bằng | J11: 1 | K11: =if(and(I11="Cao Bằng",J11=1),1,"") -> 1 | M11: 1 | N11: =if(and(I11="Cao Bằng",J11=1),1,"") -> 1 | O11: =if(J11=1,1,"") -> 1 | P11: =if(J11=1,1,"") -> 1 | Q11: =if(J11=1,1,"") -> 1 | R11: =Q11 -> 1 | S11: =N11 -> 1 | V11: Tà Lùng Quang Minh | W11: Sơn Cảng
A12: =A11+1 -> 9 | B12: 027 | C12: Lương Văn Hiện | D12: Kế hoạch - Dự án | E12: Ban Quản lý dự án | F12: Trưởng phòng Kế hoạch - Dự án | G12: Nhân viên | H12: Nam | I12: Cao Bằng | K12: =if(and(I12="Cao Bằng",J12=1),1,"") | P12: =if(J12=1,1,"") | Q12: =if(J12=1,1,"") | R12: =Q12 | S12: =N12 | V12: Phú Anh | W12: Phú Anh
A13: =A12+1 -> 10 | B13: 055 | C13: Hà Đoàn Diệu | D13: Kế hoạch - Dự án | E13: Kế hoạch và Pháp lý | F13: Chuyên viên Kế hoạch - Dự án | G13: Nhân viên | H13: Nữ | I13: Cao Bằng | J13: 1 | K13: =if(and(I13="Cao Bằng",J13=1),1,"") -> 1 | M13: 1 | N13: =if(and(I13="Cao Bằng",J13=1),1,"") -> 1 | O13: =if(J13=1,1,"") -> 1 | P13: =if(J13=1,1,"") -> 1 | Q13: =if(J13=1,1,"") -> 1 | R13: =Q13 -> 1 | S13: =N13 -> 1 | V13: Sơn Cảng | W13: Sơn Cảng
A14: =A13+1 -> 11 | B14: 013 | C14: Phạm Thị Khánh Vân | D14: Kế hoạch - Dự án | E14: Kế hoạch và Pháp lý | F14: Phó phòng Kế hoạch - Dự án | G14: Nhân viên | H14: Nữ | I14: Cao Bằng | J14: 1 | K14: =if(and(I14="Cao Bằng",J14=1),1,"") -> 1 | M14: 1 | N14: =if(and(I14="Cao Bằng",J14=1),1,"") -> 1 | O14: =if(J14=1,1,"") -> 1 | P14: =if(J14=1,1,"") -> 1 | Q14: =if(J14=1,1,"") -> 1 | R14: =Q14 -> 1 | S14: =N14 -> 1 | V14: Phú Anh | W14: Phú Anh
A15: =A14+1 -> 12 | B15: 038 | C15: Hoàng Xuân Phúc | D15: Kinh doanh | E15: Phát triển thị trường | F15: Chuyên viên Kinh doanh | G15: Nhân viên | H15: Nam | I15: Cao Bằng | J15: 1 | K15: =if(and(I15="Cao Bằng",J15=1),1,"") -> 1 | L15: 1 | M15: 1 | N15: 1 | O15: =if(J15=1,1,"") -> 1 | P15: =if(J15=1,1,"") -> 1 | Q15: =if(J15=1,1,"") -> 1 | R15: =Q15 -> 1 | S15: 1 | V15: Phú Anh | W15: Phú Anh
A16: =A15+1 -> 13 | B16: 061 | C16: Lý Thị Thanh Hiếu | D16: Kinh doanh | E16: Phát triển thị trường | F16: Chuyên viên Kinh doanh | G16: Nhân viên | H16: Nữ | I16: Cao Bằng | J16: 1 | K16: =if(and(I16="Cao Bằng",J16=1),1,"") -> 1 | M16: 1 | N16: =if(and(I16="Cao Bằng",J16=1),1,"") -> 1 | O16: =if(J16=1,1,"") -> 1 | P16: =if(J16=1,1,"") -> 1 | Q16: =if(J16=1,1,"") -> 1 | R16: =Q16 -> 1 | S16: =N16 -> 1 | V16: Sơn Cảng | W16: Sơn Cảng
A17: =A16+1 -> 14 | B17: 039 | C17: Mông Thị Hằng | D17: Kinh doanh | E17: Phát triển thị trường | F17: Nhân viên Kinh doanh | G17: Nhân viên | H17: Nữ | I17: Cao Bằng | J17: 1 | K17: =if(and(I17="Cao Bằng",J17=1),1,"") -> 1 | M17: 1 | N17: =if(and(I17="Cao Bằng",J17=1),1,"") -> 1 | O17: =if(J17=1,1,"") -> 1 | P17: =if(J17=1,1,"") -> 1 | Q17: =if(J17=1,1,"") -> 1 | R17: =Q17 -> 1 | S17: =N17 -> 1 | V17: Phú Anh | W17: Phú Anh
A18: =A17+1 -> 15 | B18: 056 | C18: Vũ Văn Hoán | D18: Kinh doanh | E18: Phát triển thị trường | F18: Phó phòng Kinh doanh | G18: Nhân viên | H18: Nam | I18: Cao Bằng | J18: 1 | L18: tự lái xe | P18: =if(J18=1,1,"") -> 1 | S18: =N18 | V18: Sơn Cảng | W18: Sơn Cảng
A19: =A18+1 -> 16 | B19: 047 | C19: Nguyễn Thị Thu Hiền | D19: Kinh doanh | E19: Xuất nhập khẩu | F19: Nhân viên Thủ tục Xuất nhập khẩu | G19: Nhân viên | H19: Nữ | I19: Cao Bằng | K19: =if(and(I19="Cao Bằng",J19=1),1,"") | U19: Không tham gia | V19: Phú Anh | W19: Phú Anh
A20: =A19+1 -> 17 | B20: 109 | C20: Đặng Thị Minh Huyền | D20: Kinh doanh | E20: Xuất nhập khẩu | F20: Nhân viên Thủ tục Xuất nhập khẩu | G20: Nhân viên | H20: Nữ | I20: Cao Bằng | K20: =if(and(I20="Cao Bằng",J20=1),1,"") | U20: Không tham gia | V20: Song Toàn | W20: Song Toàn
A21: =A20+1 -> 18 | B21: 062 | C21: Hoàng Bằng Giang | D21: Kinh doanh | E21: Xuất nhập khẩu | F21: Nhân viên Xuất nhập khẩu | G21: Nhân viên | H21: Nữ | I21: Cao Bằng | J21: 1 | K21: =if(and(I21="Cao Bằng",J21=1),1,"") -> 1 | M21: 1 | N21: =if(and(I21="Cao Bằng",J21=1),1,"") -> 1 | O21: =if(J21=1,1,"") -> 1 | P21: =if(J21=1,1,"") -> 1 | Q21: =if(J21=1,1,"") -> 1 | R21: =Q21 -> 1 | S21: =N21 -> 1 | V21: Sơn Cảng | W21: Sơn Cảng
A22: =A21+1 -> 19 | B22: 022 | C22: Hoàng Nhật Ánh | D22: Tài chính - Kế toán | E22: Kế toán | F22: Nhân viên Kế toán | G22: Nhân viên | H22: Nữ | I22: Cao Bằng | K22: =if(and(I22="Cao Bằng",J22=1),1,"") | U22: Không tham gia. Trực bãi Sơn Cảng | V22: Phú Anh | W22: Phú Anh
A23: =A22+1 -> 20 | B23: 075 | C23: Nguyễn Ngọc Ánh | D23: Tài chính - Kế toán | E23: Kế toán | F23: Nhân viên Kế toán | G23: Nhân viên | H23: Nữ | I23: Cao Bằng | U23: Không tham gia. Chị Hương đã xác nhận | V23: Sơn Cảng | W23: Sơn Cảng
A24: =A23+1 -> 21 | B24: 106 | C24: Trần Quốc Toản | D24: Vận hành | E24: An ninh | F24: Nhân viên An ninh | G24: Nhân viên | H24: Nam | I24: Cao Bằng | J24: 1 | K24: =if(and(I24="Cao Bằng",J24=1),1,"") -> 1 | M24: 1 | N24: =if(and(I24="Cao Bằng",J24=1),1,"") -> 1 | O24: =if(J24=1,1,"") -> 1 | P24: =if(J24=1,1,"") -> 1 | Q24: =if(J24=1,1,"") -> 1 | R24: =Q24 -> 1 | S24: =N24 -> 1 | V24: Sơn Cảng | W24: Sơn Cảng
A25: =A24+1 -> 22 | B25: 031 | C25: Lương Duy Thái | D25: Vận hành | E25: An ninh | F25: Trưởng ca An ninh | G25: Nhân viên | H25: Nam | I25: Cao Bằng | J25: 1 | K25: =if(and(I25="Cao Bằng",J25=1),1,"") -> 1 | M25: 1 | N25: =if(and(I25="Cao Bằng",J25=1),1,"") -> 1 | O25: =if(J25=1,1,"") -> 1 | P25: =if(J25=1,1,"") -> 1 | Q25: =if(J25=1,1,"") -> 1 | R25: =Q25 -> 1 | S25: =N25 -> 1 | V25: Phú Anh | W25: Phú Anh
A26: =A25+1 -> 23 | B26: 076 | C26: Nguyễn Hoài Nam | D26: Vận hành | E26: Điều phối | F26: Công nhân bốc xếp | G26: Nhân viên | H26: Nam | I26: Cao Bằng | J26: 1 | K26: =if(and(I26="Cao Bằng",J26=1),1,"") -> 1 | M26: 1 | N26: =if(and(I26="Cao Bằng",J26=1),1,"") -> 1 | O26: =if(J26=1,1,"") -> 1 | P26: =if(J26=1,1,"") -> 1 | Q26: =if(J26=1,1,"") -> 1 | R26: =Q26 -> 1 | S26: =N26 -> 1 | V26: Sơn Cảng | W26: Sơn Cảng
A27: =A26+1 -> 24 | B27: 081 | C27: Tăng Văn Tuấn | D27: Vận hành | E27: Điều phối | F27: Công nhân bốc xếp | G27: Nhân viên | H27: Nam | I27: Cao Bằng | J27: 1 | K27: =if(and(I27="Cao Bằng",J27=1),1,"") -> 1 | M27: 1 | N27: =if(and(I27="Cao Bằng",J27=1),1,"") -> 1 | O27: =if(J27=1,1,"") -> 1 | P27: =if(J27=1,1,"") -> 1 | Q27: =if(J27=1,1,"") -> 1 | R27: =Q27 -> 1 | S27: =N27 -> 1 | V27: Sơn Cảng | W27: Sơn Cảng
A28: =A27+1 -> 25 | B28: 092 | C28: Hoàng Hoài Phong | D28: Vận hành | E28: Điều phối | F28: Công nhân bốc xếp | G28: Nhân viên | H28: Nam | I28: Cao Bằng | K28: =if(and(I28="Cao Bằng",J28=1),1,"") | N28: =if(and(I28="Cao Bằng",J28=1),1,"") | O28: =if(J28=1,1,"") | P28: =if(J28=1,1,"") | Q28: =if(J28=1,1,"") | R28: =Q28 | S28: =N28 | V28: Sơn Cảng | W28: Sơn Cảng
A29: =A28+1 -> 26 | B29: 094 | C29: Luân Văn Mạnh | D29: Vận hành | E29: Điều phối | F29: Công nhân bốc xếp | G29: Nhân viên | H29: Nam | I29: Cao Bằng | J29: 1 | K29: =if(and(I29="Cao Bằng",J29=1),1,"") -> 1 | M29: 1 | N29: =if(and(I29="Cao Bằng",J29=1),1,"") -> 1 | O29: =if(J29=1,1,"") -> 1 | P29: =if(J29=1,1,"") -> 1 | Q29: =if(J29=1,1,"") -> 1 | R29: =Q29 -> 1 | S29: =N29 -> 1 | V29: Sơn Cảng | W29: Sơn Cảng
A30: =A29+1 -> 27 | B30: 095 | C30: Nguyễn Văn Bắc | D30: Vận hành | E30: Điều phối | F30: Công nhân bốc xếp | G30: Nhân viên | H30: Nam | I30: Cao Bằng | K30: =if(and(I30="Cao Bằng",J30=1),1,"") | N30: =if(and(I30="Cao Bằng",J30=1),1,"") | O30: =if(J30=1,1,"") | P30: =if(J30=1,1,"") | Q30: =if(J30=1,1,"") | R30: =Q30 | S30: =N30 | V30: Sơn Cảng | W30: Sơn Cảng
A31: =A30+1 -> 28 | B31: 126 | C31: Lục Văn Quảng | D31: Vận hành | E31: Điều phối | F31: Công nhân bốc xếp | G31: Nhân viên | H31: Nam | I31: Cao Bằng | J31: 1 | K31: =if(and(I31="Cao Bằng",J31=1),1,"") -> 1 | M31: 1 | N31: =if(and(I31="Cao Bằng",J31=1),1,"") -> 1 | O31: =if(J31=1,1,"") -> 1 | P31: =if(J31=1,1,"") -> 1 | Q31: =if(J31=1,1,"") -> 1 | R31: =Q31 -> 1 | S31: =N31 -> 1 | V31: Sơn Cảng | W31: Sơn Cảng
A32: =A31+1 -> 29 | B32: 133 | C32: Đàm Thị Hân | D32: Vận hành | E32: Điều phối | F32: Công nhân bốc xếp | G32: Nhân viên | H32: Nữ | I32: Cao Bằng | J32: 1 | K32: =if(and(I32="Cao Bằng",J32=1),1,"") -> 1 | M32: 1 | N32: =if(and(I32="Cao Bằng",J32=1),1,"") -> 1 | O32: =if(J32=1,1,"") -> 1 | P32: =if(J32=1,1,"") -> 1 | Q32: =if(J32=1,1,"") -> 1 | R32: =Q32 -> 1 | S32: =N32 -> 1 | V32: Sơn Cảng | W32: Sơn Cảng
A33: =A32+1 -> 30 | B33: 134 | C33: Đàm Thị Vụ | D33: Vận hành | E33: Điều phối | F33: Công nhân bốc xếp | G33: Nhân viên | H33: Nữ | I33: Cao Bằng | J33: 1 | K33: =if(and(I33="Cao Bằng",J33=1),1,"") -> 1 | M33: 1 | N33: =if(and(I33="Cao Bằng",J33=1),1,"") -> 1 | O33: =if(J33=1,1,"") -> 1 | P33: =if(J33=1,1,"") -> 1 | Q33: =if(J33=1,1,"") -> 1 | R33: =Q33 -> 1 | S33: =N33 -> 1 | V33: Sơn Cảng | W33: Sơn Cảng
A34: =A33+1 -> 31 | B34: 135 | C34: Đàm Thị Liệng | D34: Vận hành | E34: Điều phối | F34: Công nhân bốc xếp | G34: Nhân viên | H34: Nữ | I34: Cao Bằng | J34: 1 | K34: =if(and(I34="Cao Bằng",J34=1),1,"") -> 1 | M34: 1 | N34: =if(and(I34="Cao Bằng",J34=1),1,"") -> 1 | O34: =if(J34=1,1,"") -> 1 | P34: =if(J34=1,1,"") -> 1 | Q34: =if(J34=1,1,"") -> 1 | R34: =Q34 -> 1 | S34: =N34 -> 1 | V34: Sơn Cảng | W34: Sơn Cảng
A35: =A34+1 -> 32 | B35: 139 | C35: Chu Thị Hồng | D35: Vận hành | E35: Điều phối | F35: Công nhân bốc xếp | G35: Nhân viên | H35: Nữ | I35: Cao Bằng | J35: 1 | K35: =if(and(I35="Cao Bằng",J35=1),1,"") -> 1 | M35: 1 | N35: =if(and(I35="Cao Bằng",J35=1),1,"") -> 1 | O35: =if(J35=1,1,"") -> 1 | P35: =if(J35=1,1,"") -> 1 | Q35: =if(J35=1,1,"") -> 1 | R35: =Q35 -> 1 | S35: =N35 -> 1 | V35: Sơn Cảng | W35: Sơn Cảng
A36: =A35+1 -> 33 | B36: 034 | C36: Hoàng Văn Võ | D36: Vận hành | E36: Điều phối | F36: Nhân viên Điều phối | G36: Nhân viên | H36: Nam | I36: Cao Bằng | J36: 1 | K36: =if(and(I36="Cao Bằng",J36=1),1,"") -> 1 | M36: 1 | N36: =if(and(I36="Cao Bằng",J36=1),1,"") -> 1 | O36: =if(J36=1,1,"") -> 1 | P36: =if(J36=1,1,"") -> 1 | Q36: =if(J36=1,1,"") -> 1 | R36: =Q36 -> 1 | S36: =N36 -> 1 | V36: Phú Anh | W36: Phú Anh
A37: =A36+1 -> 34 | B37: 054 | C37: Nguyễn Cao Cường | D37: Vận hành | E37: Điều phối | F37: Nhân viên Điều phối | G37: Nhân viên | H37: Nam | I37: Cao Bằng | J37: 1 | K37: =if(and(I37="Cao Bằng",J37=1),1,"") -> 1 | M37: 1 | N37: =if(and(I37="Cao Bằng",J37=1),1,"") -> 1 | O37: =if(J37=1,1,"") -> 1 | P37: =if(J37=1,1,"") -> 1 | Q37: =if(J37=1,1,"") -> 1 | R37: =Q37 -> 1 | S37: =N37 -> 1 | V37: Phú Anh | W37: Phú Anh
A38: =A37+1 -> 35 | B38: 030 | C38: Lương Văn Thành | D38: Vận hành | E38: Điều phối | F38: Nhân viên nghiệp vụ cổng cảng và kho bãi | G38: Nhân viên | H38: Nam | I38: Cao Bằng | J38: 1 | K38: =if(and(I38="Cao Bằng",J38=1),1,"") -> 1 | M38: 1 | N38: =if(and(I38="Cao Bằng",J38=1),1,"") -> 1 | O38: =if(J38=1,1,"") -> 1 | P38: =if(J38=1,1,"") -> 1 | Q38: =if(J38=1,1,"") -> 1 | R38: =Q38 -> 1 | S38: =N38 -> 1 | V38: Phú Anh | W38: Phú Anh
A39: =A38+1 -> 36 | B39: 006 | C39: Trịnh Công Nguyên | D39: Vận hành | E39: Điều phối | F39: Trưởng bộ phận nghiệp vụ cổng cảng và kho bãi | G39: Nhân viên | H39: Nam | I39: Cao Bằng | J39: 1 | K39: =if(and(I39="Cao Bằng",J39=1),1,"") -> 1 | M39: 1 | N39: =if(and(I39="Cao Bằng",J39=1),1,"") -> 1 | O39: =if(J39=1,1,"") -> 1 | P39: =if(J39=1,1,"") -> 1 | Q39: =if(J39=1,1,"") -> 1 | R39: =Q39 -> 1 | S39: =N39 -> 1 | V39: Phú Anh | W39: Phú Anh
A40: =A39+1 -> 37 | B40: 046 | C40: Hoàng Minh Hải | D40: Vận hành | E40: Điều phối | F40: Trưởng ca Điều phối | G40: Nhân viên | H40: Nam | I40: Cao Bằng | K40: =if(and(I40="Cao Bằng",J40=1),1,"") | N40: =if(and(I40="Cao Bằng",J40=1),1,"") | O40: =if(J40=1,1,"") | P40: =if(J40=1,1,"") | Q40: =if(J40=1,1,"") | R40: =Q40 | S40: =N40 | V40: Phú Anh | W40: Phú Anh
...

Sheet Menu
A1: MENU CÁC BỮA
B3: Trưa 5/10 | D3: Tối 5/10 Gala | F3: Trưa 6/10
B4: Nhà hàng Thiên Anh | D4: Nhà hàng Thăng Long | F4: Nhà hàng Thiên Tân
B5: Dự kiến 220k cả VAT | D5: 380k cả VAT | F5: Dự kiến 220k cả VAT
A7: 1 | B7: Nộm bò hoa chuối | D7: Súp hải sản - 1 bát | F7: Salad Thiên Tân
A8: =A7+1 -> 2 | B8: Mực nấu chua | D8: Nộm xoài hải sản - 1 đĩa | F8: Ngao hoa nấu chua/ nấu Thái
A9: =A8+1 -> 3 | B9: Tôm hấp sả | D9: Tu hài bọc bạc hấp – 1 con/k | F9: Móng tay xào chua ngọt
A10: =A9+1 -> 4 | B10: Cá chiên xù | D10: Mực nướng lá chuối – 0.8kg | F10: Thăn cá vược tẩm vừng chiên
A11: =A10+1 -> 5 | B11: Mẹt bún + chả nem hải sản Thiên Anh | D11: Tôm chiên Hoàng Bào – 0.5kg | F11: Hàu nướng mỡ hành
A12: =A11+1 -> 6 | B12: Mắm tép chưng thịt | D12: Cá song hấp đậu non kèm đồ cuốn – 1.3kg | F12: Miến om hải sản | I12: bỏ | J12: Mực hấp cần thơm
A13: =A12+1 -> 7 | B13: Rau cải luộc chấm mắm trứng | D13: Chân giò hầm bát bảo + bánh mỳ | F13: Đậu hũ non chiên xù
A14: =A13+1 -> 8 | B14: Canh bầu tôm | D14: Củ quả luộc chấm muối vừng | F14: Thịt ba chỉ rang cháy cạnh
A15: =A14+1 -> 9 | B15: Cơm trắng | D15: Canh chua hải sản | F15: Rau muống xào tỏi
A16: =A15+1 -> 10 | B16: Tráng miệng | D16: Cơm rang hải sản | F16: Canh chua đầu cá vược
A17: =A16+1 -> 11 | D17: Tráng miệng | F17: Cơm
A18: =A17+1 -> 12 | D18: Mực khô nướng (mang ngoài vào) | F18: Tráng miệng

Sheet Agenda Gala
A1: CHƯƠNG TRÌNH GALA DINNER
A2: Tối ngày 06/10/2026
A3: Địa điểm: Nhà hàng Thiên Anh
A5: Thời gian | B5: Nội dung | C5: Thực hiện | D5: Yêu cầu chuẩn bị | E5: Âm nhạc
A6: 18:00–18:30 | B6: Đón khách, check-in, chụp ảnh | C6: Lễ tân, Truyền thông | D6: Backdrop, hashtag, nhạc nền, sơ đồ bàn
A7: 18:30–18:35 | B7: Tiết mục văn nghệ mở màn | C7: Đội văn nghệ Hạ Long | D7: Nhạc, ánh sáng, sân khấu
A8: 18:35–18:42 | B8: Tuyên bố lý do, giới thiệu đại biểu | C8: MC | D8: Danh sách đại biểu
A9: 18:42–18:47 | B9: Trình chiếu video hành trình một năm | C9: Kỹ thuật | D9: Video dài 3–5 phút
A10: 18:47–18:57 | B10: Phát biểu của đại diện Ban Lãnh đạo | C10: Đại diện Ban Lãnh đạo | D10: Bài phát biểu, micro
A11: 18:57–19:10 | B11: Nghi thức kỷ niệm một năm ra mắt thương hiệu: Cắt bánh | C11: HĐQT, Ban Lãnh đạo | D11: Bánh sinh nhật + nến, rượu, ly, nhạc Happy birthday và các hiệu ứng liên quan
A12: 19:22–19:27 | B12: Nâng ly chúc mừng và khai tiệc | C12: Ban Lãnh đạo, khách mời | D12: Nhạc chúc mừng
A13: 19:27–19:50 | B13: Dùng tiệc | D13: Nhạc nền ăn tiệc
A14: 19:50 - 19:55 | B14: Văn nghệ mở màn phần 2 | C14: Nhóm văn nghệ Cao Bằng
A15: 19:55 - 20:05 | B15: Chúc mừng sinh nhật nhân viên tháng 9 & tháng 10 | C15: TGĐ, Nhân viên có sinh nhật trong tháng | D15: Check Ms. Trang có đi ko để chúc mừng sinh nhật
A16: 20:05 - 20:15 | B16: Trò chơi cá nhân 1 | C16: MC, nhân viên | D16: Quà tặng, đạo cụ
A17: 20:15 - 20:25 | B17: Bốc thăm may mắn - Giải May mắn | C17: MC, Ban Lãnh đạo | D17: Phiếu bốc thăm, quà tặng
A18: 20:25 - 20: 35 | B18: Trò chơi tập thể | C18: MC, nhân viên | D18: Nhạc tạo hình
A19: 20:35 - 20: 40 | B19: Văn nghệ | C19: Cao Bằng
A20: 20:40 - 20:55 | B20: Bốc thăm may mắn – 10 Giải Ba, 03 Giải Nhì, 01 Giải Nhất | C20: MC, HĐQT | D20: Giải thưởng
A21: 20:45–20:55 | B21: Phát biểu cảm ơn, khép lại chương trình | C21: Đại diện Ban Tổ chức | D21: Micro, nhạc nền
A22: 20:55 - 21:00 | B22: Văn nghệ sôi động | C22: Hạ Long lead
A23: 0.875 | B23: Kết thúc | C23: Toàn thể khách mời

Sheet Chi phí
A1: DỰ TRÙ KINH PHÍ
H3: Ngân sách
A4: STT | B4: Chi tiết | C4: Đơn vị tính | D4: Số lượng | E4: Đơn giá | F4: Thành tiền | G4: Ghi chú | H4: Công ty | I4: Công đoàn
A5: A | B5: Tổ chức chương trình I + II + III | F5: =F6+F15+F31 -> 146660000
A6: I | B6: Phòng nghỉ và di chuyển | F6: =sum(F7:F14) -> 49400000
A7: 1 | B7: Thuê xe vận chuyển 34 ghế | C7: lần | D7: 1 | E7: 16000000 | F7: =E7*D7 -> 16000000 | G7: Tài xế xe tự túc ăn ngủ. Giá đã bao gồm VAT | I7: =F7 -> 16000000
A8: =A7+1 -> 2 | B8: Banner treo xe | C8: cái | D8: =D7 -> 1 | E8: 500000 | F8: =E8*D8 -> 500000 | G8: 50 * 150 cm | H8: =F8 -> 500000
A9: =A8+1 -> 3 | B9: Khách sạn kèm ăn sáng | C9: lần | D9: 1 | E9: ='Sắp xếp phòng'!N5 -> 9200000 | F9: =E9*D9 -> 9200000 | G9: Khách sạn New Stars | H9: =F9 -> 9200000 | J9: To do: Update lại chi phí
A10: =A9+1 -> 4 | B10: Ăn sáng ngày 1 cho nhân viên Cao Bằng (trên đường đi) | C10: nhân viên | D10: ='Danh sách MASTER'!N119 -> 34 | E10: 50000 | F10: =E10*D10 -> 1700000 | H10: =F10 -> 1700000 | L10: 55000 | M10: =0.5*1.5*L10 -> 41250
A11: =A10+1 -> 5 | B11: Ăn tối ngày 2 cho nhân viên Cao Bằng (trên đường đi) | C11: nhân viên | D11: =D10 -> 34 | E11: 200000 | F11: =E11*D11 -> 6800000 | H11: =F11 -> 6800000
A12: =A11+1 -> 6 | B12: Đồ ăn nhẹ cho đoàn theo xe | C12: lần | D12: 2 | E12: 2000000 | F12: =E12*D12 -> 4000000
A13: =A12+1 -> 7 | B13: Nước uống theo xe | C13: thùng | D13: 8 | E13: 80000 | F13: =E13*D13 -> 640000 | G13: Nước 350ml
A14: =A13+1 -> 8 | B14: Ăn trưa ngày 1 cho toàn đoàn | C14: suất | D14: ='Danh sách MASTER'!O119 -> 44 | E14: 240000 | F14: =E14*D14 -> 10560000 | G14: Thiên Anh (Menu 220k, 20k đồ uống) | H14: =F14 -> 10560000
A15: II | B15: Chương trình Gala | F15: =sum(F16:F30) -> 58200000
A16: 1 | B16: Ăn tiệc gala | C16: suất | D16: ='Danh sách MASTER'!P119 -> 65 | E16: 380000 | F16: =E16*D16 -> 24700000 | G16: Màn led chạy cửa đón Độ phân giải 1600 x 160 px Kích thước : 0,82 x 6m Kích thước khung backdrop chụp ảnh để sảnh : cao 3m x 3,5m
A17: =A16+1 -> 2 | B17: Âm thanh ánh sáng | C17: lần | D17: 1 | E17: 2000000 | F17: =E17*D17 -> 2000000
A18: =A17+1 -> 3 | B18: Mực khô | C18: kg | D18: 2 | E18: 1800000 | F18: =E18*D18 -> 3600000
A19: =A18+1 -> 4 | B19: Đồ uống gala | C19: suất | D19: =D16 -> 65 | E19: 50000 | F19: =E19*D19 -> 3250000
A20: =A19+1 -> 5 | B20: Rượu trắng | C20: lit | D20: 0 | E20: 50000 | F20: =E20*D20 -> 0 | G20: 1 can: đã có sẵn
A21: =A20+1 -> 6 | B21: Chi phí mang đồ uống vào | C21: suất | D21: 0 | E21: 10000 | F21: =E21*D21 -> 0
A22: =A21+1 -> 7 | B22: Bánh sinh nhật | C22: cái | D22: 1 | E22: 650000 | F22: =E22*D22 -> 650000
A23: =A22+1 -> 8 | B23: Bốc thăm may mắn | C23: lần | D23: 1 | E23: 10000000 | F23: =E23*D23 -> 10000000
A24: =A23+1 -> 9 | B24: Thuê trang phục Cao Bằng | C24: lần | D24: 1 | E24: 2300000 | F24: =E24*D24 -> 2300000 | G24: Tổng HL + CB = 6tr | J24: Tổng HL + CB = 6tr
A25: =A24+1 -> 10 | B25: Hỗ trợ make up Cao Bằng | C25: lần | D25: 1 | E25: 1200000 | F25: =E25*D25 -> 1200000 | G25: 4 pax
A26: =A25+1 -> 11 | B26: Thuê trang phục Quảng Ninh | C26: lần | D26: 1 | E26: 1000000 | F26: =E26*D26 -> 1000000
A27: =A26+1 -> 12 | B27: Hỗ trợ make up Quảng Ninh | C27: lần | D27: 1 | E27: 1500000 | F27: =E27*D27 -> 1500000 | G27: 5 pax
A28: =A27+1 -> 13 | B28: Thuê trang phục MC | C28: người | D28: 2 | E28: 500000 | F28: =E28*D28 -> 1000000 | L28: =L10*3*3.5 -> 577500
A29: =A28+1 -> 14 | B29: Trang trí backdrop, hashtag chụp ảnh | C29: lần | D29: 1 | E29: 2000000 | F29: =E29*D29 -> 2000000
A30: =A29+1 -> 15 | B30: Quay film, chụp ảnh | C30: lần | D30: 1 | E30: 5000000 | F30: =E30*D30 -> 5000000
A31: III | B31: Các chương trình thăm quan | F31: =sum(F32:F35) -> 39060000
A32: 1 | B32: Vé xe bus 2 tầng | C32: vé | E32: 159000 | F32: =E32*D32 -> 0 | G32: Check Ánh + Tâm tourguide
A33: =A32+1 -> 2 | B33: Thuê tàu Danova | C33: lần | D33: 1 | E33: 6000000 | F33: =E33*D33 -> 6000000
A34: =A33+1 -> 3 | B34: Vé thắng cảnh | C34: người | D34: ='Danh sách MASTER'!Q119 -> 57 | E34: 330000 | F34: =E34*D34 -> 18810000
A35: =A34+1 -> 4 | B35: Ăn trưa ngày 2 | C35: suất | D35: =D34 -> 57 | E35: 250000 | F35: =E35*D35 -> 14250000
A36: B | B36: Quà tặng nhân viên & chi phí khác | F36: =sum(F37:F39) -> 53250000
A37: 1 | B37: Quà tặng nhân viên | C37: nhân viên | D37: 100 | E37: 500000 | F37: =E37*D37 -> 50000000 | G37: Chi trả vào lương của nhân viên. Số lượng chính xác được cập nhật tại thời điểm chi trả
A38: 2 | B38: Huy hiệu cài áo tặng cán bộ quản lý/ HĐQT | C38: cái | D38: 50 | E38: 60000 | F38: =E38*D38 -> 3000000 | G38: 50 cái/ lô
A39: 3 | B39: Thắp hương tại vp (thứ 7 ngày 3/10/2026) | C39: lần | D39: 1 | E39: 250000 | F39: =E39*D39 -> 250000
B40: Tổng cộng A + B | F40: =F36+F5 -> 199910000
B45: Tính chi phí các phương án thuê tàu THAM KHẢO
...

Sheet Sắp xếp phòng
A1: DANH SÁCH SẮP XẾP PHÒNG KHÁCH SẠN - Update ngày 02/10/2026 (10h00) | F1: Loại phòng | G1: Số lượng phòng | H1: Ký hiệu | I1: Số người | J1: Giường | K1: Cách đặt mã phòng | L1: Ghi chú | M1: Đơn giá | N1: Thành tiền | O1: Check số người
A2: Khách sạn NEWSTAR HALONG HOTEL | F2: Phòng đôi loại 1 giường | G2: =IFERROR(__xludf.DUMMYFUNCTION("COUNTUNIQUEIFS($H$7:$H$36, $H$7:$H$36, H2 & ""*"")"),5.0) -> 5 | H2: DBL | I2: 2 | J2: 1 giường 1m8 | K2: DBL 1, DBL 2, .... | L2: Ưu tiên phòng DBL cho nữ | M2: 600000 | N2: =M2*G2 -> 3000000 | O2: =G2*I2 -> 10
F3: Phòng đôi loại 2 giường | G3: =IFERROR(__xludf.DUMMYFUNCTION("COUNTUNIQUEIFS($H$7:$H$36, $H$7:$H$36, H3 & ""*"")"),5.0) -> 5 | H3: TWN | I3: 2 | J3: 2 giường 1m2 | K3: TWN 1, TWN 2 .... TWN 10 | M3: 600000 | N3: =M3*G3 -> 3000000 | O3: =G3*I3 -> 10
F4: Phòng ba | G4: =IFERROR(__xludf.DUMMYFUNCTION("COUNTUNIQUEIFS($H$7:$H$36, $H$7:$H$36, H4 & ""*"")"),4.0) -> 4 | H4: TRP | I4: 3 | J4: 3 giường 1m2 | K4: TRP 1 ... TRP 6 | L4: Ưu tiên đặt phòng ngủ 2, lẻ người mới đặt phòng ngủ 3 | M4: 800000 | N4: =M4*G4 -> 3200000 | O4: =G4*I4 -> 12
A5: Cách sắp xếp: Những người cùng phòng thì cắt lên gần nhau, đặt cùng mã phòng. KHÔNG MERGE Ô | N5: =sum(N2:N4) -> 9200000 | O5: =sum(O2:O4) -> 32 | P5: =I39 -> 32 | Q5: =P5=O5 -> TRUE
A6: STT | B6: Mã nhân viên | C6: Họ và tên | D6: Phòng ban | E6: Bộ phận | F6: Vị trí | G6: Giới tính | H6: Mã phòng | I6: Check đặt phòng ks | J6: Công ty xuất hoá đơn
A7: 1 | B7: 055 | C7: Hà Đoàn Diệu | D7: Kế hoạch - Dự án | E7: Kế hoạch và Pháp lý | F7: Chuyên viên Kế hoạch - Dự án | G7: Nữ | H7: DBL1 | I7: =if(isna(vlookup(B7,'Danh sách MASTER'!$B$3:$M$119,12,0)),0,vlookup(B7,'Danh sách MASTER'!$B$3:$M$119,12,0)) -> 1 | J7: =vlookup(B7,'Danh sách MASTER'!$B$3:$W$118,22,0) -> Sơn Cảng
A8: =A7+1 -> 2 | B8: 013 | C8: Phạm Thị Khánh Vân | D8: Kế hoạch - Dự án | E8: Kế hoạch và Pháp lý | F8: Phó phòng Kế hoạch - Dự án | G8: Nữ | H8: DBL1 | I8: =if(isna(vlookup(B8,'Danh sách MASTER'!$B$3:$M$119,12,0)),0,vlookup(B8,'Danh sách MASTER'!$B$3:$M$119,12,0)) -> 1 | J8: =vlookup(B8,'Danh sách MASTER'!$B$3:$V$118,21,0) -> Phú Anh
A9: =A8+1 -> 3 | B9: 016 | C9: Bế Ngọc Dung | D9: Hành chính - Nhân sự | E9: Hành chính - Nhân sự | F9: Nhân viên Hành chính - Nhân sự | G9: Nữ | H9: DBL2 | I9: =if(isna(vlookup(B9,'Danh sách MASTER'!$B$3:$M$119,12,0)),0,vlookup(B9,'Danh sách MASTER'!$B$3:$M$119,12,0)) -> 1 | J9: =vlookup(B9,'Danh sách MASTER'!$B$3:$V$118,21,0) -> Phú Anh
A10: =A9+1 -> 4 | B10: 039 | C10: Mông Thị Hằng | D10: Kinh doanh | E10: Phát triển thị trường | F10: Nhân viên Kinh doanh | G10: Nữ | H10: DBL2 | I10: =if(isna(vlookup(B10,'Danh sách MASTER'!$B$3:$M$119,12,0)),0,vlookup(B10,'Danh sách MASTER'!$B$3:$M$119,12,0)) -> 1 | J10: =vlookup(B10,'Danh sách MASTER'!$B$3:$V$118,21,0) -> Phú Anh
A11: =A10+1 -> 5 | B11: 061 | C11: Lý Thị Thanh Hiếu | D11: Kinh doanh | E11: Phát triển thị trường | F11: Chuyên viên Kinh doanh | G11: Nữ | H11: DBL3 | I11: =if(isna(vlookup(B11,'Danh sách MASTER'!$B$3:$M$119,12,0)),0,vlookup(B11,'Danh sách MASTER'!$B$3:$M$119,12,0)) -> 1 | J11: =vlookup(B11,'Danh sách MASTER'!$B$3:$V$118,21,0) -> Sơn Cảng
A12: =A11+1 -> 6 | B12: 062 | C12: Hoàng Bằng Giang | D12: Kinh doanh | E12: Xuất nhập khẩu | F12: Nhân viên Xuất nhập khẩu | G12: Nữ | H12: DBL3 | I12: =if(isna(vlookup(B12,'Danh sách MASTER'!$B$3:$M$119,12,0)),0,vlookup(B12,'Danh sách MASTER'!$B$3:$M$119,12,0)) -> 1 | J12: =vlookup(B12,'Danh sách MASTER'!$B$3:$V$118,21,0) -> Sơn Cảng
A13: =A12+1 -> 7 | B13: 133 | C13: Đàm Thị Hân | D13: Vận hành | E13: Điều phối | F13: Công nhân bốc xếp | G13: Nữ | H13: DBL4 | I13: =if(isna(vlookup(B13,'Danh sách MASTER'!$B$3:$M$119,12,0)),0,vlookup(B13,'Danh sách MASTER'!$B$3:$M$119,12,0)) -> 1 | J13: =vlookup(B13,'Danh sách MASTER'!$B$3:$V$118,21,0) -> Sơn Cảng
A14: =A13+1 -> 8 | B14: 134 | C14: Đàm Thị Vụ | D14: Vận hành | E14: Điều phối | F14: Công nhân bốc xếp | G14: Nữ | H14: DBL4 | I14: =if(isna(vlookup(B14,'Danh sách MASTER'!$B$3:$M$119,12,0)),0,vlookup(B14,'Danh sách MASTER'!$B$3:$M$119,12,0)) -> 1 | J14: =vlookup(B14,'Danh sách MASTER'!$B$3:$V$118,21,0) -> Sơn Cảng
A15: =A14+1 -> 9 | B15: 135 | C15: Đàm Thị Liệng | D15: Vận hành | E15: Điều phối | F15: Công nhân bốc xếp | G15: Nữ | H15: DBL5 | I15: =if(isna(vlookup(B15,'Danh sách MASTER'!$B$3:$M$119,12,0)),0,vlookup(B15,'Danh sách MASTER'!$B$3:$M$119,12,0)) -> 1 | J15: =vlookup(B15,'Danh sách MASTER'!$B$3:$V$118,21,0) -> Sơn Cảng
A16: =A15+1 -> 10 | B16: 139 | C16: Chu Thị Hồng | D16: Vận hành | E16: Điều phối | F16: Công nhân bốc xếp | G16: Nữ | H16: DBL5 | I16: =if(isna(vlookup(B16,'Danh sách MASTER'!$B$3:$M$119,12,0)),0,vlookup(B16,'Danh sách MASTER'!$B$3:$M$119,12,0)) -> 1 | J16: =vlookup(B16,'Danh sách MASTER'!$B$3:$V$118,21,0) -> Sơn Cảng
A17: =A16+1 -> 11 | B17: 087 | C17: Đinh Thị Bờ | D17: Hành chính - Nhân sự | E17: Hành chính | F17: Nhân viên bếp | G17: Nữ | H17: TRP1 | I17: =if(isna(vlookup(B17,'Danh sách MASTER'!$B$3:$M$119,12,0)),0,vlookup(B17,'Danh sách MASTER'!$B$3:$M$119,12,0)) -> 1 | J17: =vlookup(B17,'Danh sách MASTER'!$B$3:$V$118,21,0) -> Sơn Cảng
A18: =A17+1 -> 12 | B18: 037 | C18: Phạm Thị Hằng | D18: Hành chính - Nhân sự | E18: Hành chính | F18: Nhân viên tạp vụ | G18: Nữ | H18: TRP1 | I18: =if(isna(vlookup(B18,'Danh sách MASTER'!$B$3:$M$119,12,0)),0,vlookup(B18,'Danh sách MASTER'!$B$3:$M$119,12,0)) -> 1 | J18: =vlookup(B18,'Danh sách MASTER'!$B$3:$V$118,21,0) -> Phú Anh
A19: =A18+1 -> 13 | B19: 068 | C19: Hà Thị Hòa | D19: Hành chính - Nhân sự | E19: Hành chính | F19: Nhân viên tạp vụ | G19: Nữ | H19: TRP1 | I19: =if(isna(vlookup(B19,'Danh sách MASTER'!$B$3:$M$119,12,0)),0,vlookup(B19,'Danh sách MASTER'!$B$3:$M$119,12,0)) -> 1 | J19: =vlookup(B19,'Danh sách MASTER'!$B$3:$V$118,21,0) -> Sơn Cảng
A20: =A19+1 -> 14 | B20: 106 | C20: Trần Quốc Toản | D20: Vận hành | E20: An ninh | F20: Nhân viên An ninh | G20: Nam | H20: TRP2 | I20: =if(isna(vlookup(B20,'Danh sách MASTER'!$B$3:$M$119,12,0)),0,vlookup(B20,'Danh sách MASTER'!$B$3:$M$119,12,0)) -> 1 | J20: =vlookup(B20,'Danh sách MASTER'!$B$3:$V$118,21,0) -> Sơn Cảng
A21: =A20+1 -> 15 | B21: 054 | C21: Nguyễn Cao Cường | D21: Vận hành | E21: Điều phối | F21: Nhân viên Điều phối | G21: Nam | H21: TRP2 | I21: =if(isna(vlookup(B21,'Danh sách MASTER'!$B$3:$M$119,12,0)),0,vlookup(B21,'Danh sách MASTER'!$B$3:$M$119,12,0)) -> 1 | J21: =vlookup(B21,'Danh sách MASTER'!$B$3:$V$118,21,0) -> Phú Anh
A22: =A21+1 -> 16 | B22: 007 | C22: Nguyễn Xuân Thành | D22: Vận hành | E22: Hành chính | F22: Trưởng bộ phận Công nghệ thông tin | G22: Nam | H22: TRP2 | I22: =if(isna(vlookup(B22,'Danh sách MASTER'!$B$3:$M$119,12,0)),0,vlookup(B22,'Danh sách MASTER'!$B$3:$M$119,12,0)) -> 1 | J22: =vlookup(B22,'Danh sách MASTER'!$B$3:$V$118,21,0) -> Phú Anh
A23: =A22+1 -> 17 | B23: 130 | C23: Nông Quốc Việt | D23: Vận hành | E23: Hành chính | F23: Nhân viên Công nghệ thông tin | G23: Nam | H23: TRP3 | I23: =if(isna(vlookup(B23,'Danh sách MASTER'!$B$3:$M$119,12,0)),0,vlookup(B23,'Danh sách MASTER'!$B$3:$M$119,12,0)) -> 1 | J23: =vlookup(B23,'Danh sách MASTER'!$B$3:$V$118,21,0) -> Sơn Cảng
A24: =A23+1 -> 18 | B24: 129 | C24: Nông Hồng Hưng | D24: Vận hành | E24: Vận hành thiết bị | F24: Nhân viên vận hành thiết bị | G24: Nam | H24: TRP3 | I24: =if(isna(vlookup(B24,'Danh sách MASTER'!$B$3:$M$119,12,0)),0,vlookup(B24,'Danh sách MASTER'!$B$3:$M$119,12,0)) -> 1 | J24: =vlookup(B24,'Danh sách MASTER'!$B$3:$V$118,21,0) -> Sơn Cảng
A25: =A24+1 -> 19 | B25: 036 | C25: Hoàng Văn Sinh | D25: Vận hành | E25: Kỹ thuật | F25: Nhân viên Kỹ thuật | G25: Nam | H25: TRP3 | I25: =if(isna(vlookup(B25,'Danh sách MASTER'!$B$3:$M$119,12,0)),0,vlookup(B25,'Danh sách MASTER'!$B$3:$M$119,12,0)) -> 1 | J25: =vlookup(B25,'Danh sách MASTER'!$B$3:$V$118,21,0) -> Phú Anh
A26: =A25+1 -> 20 | B26: 066 | C26: Nguyễn Quang Đạt | D26: Kế hoạch - Dự án | E26: Ban Quản lý dự án | F26: Trưởng ban Quản lý dự án | G26: Nam | H26: TWN1 | I26: =if(isna(vlookup(B26,'Danh sách MASTER'!$B$3:$M$119,12,0)),0,vlookup(B26,'Danh sách MASTER'!$B$3:$M$119,12,0)) -> 1 | J26: =vlookup(B26,'Danh sách MASTER'!$B$3:$V$118,21,0) -> Tà Lùng Quang Minh
A27: =A26+1 -> 21 | B27: 031 | C27: Lương Duy Thái | D27: Vận hành | E27: An ninh | F27: Trưởng ca An ninh | G27: Nam | H27: TWN1 | I27: =if(isna(vlookup(B27,'Danh sách MASTER'!$B$3:$M$119,12,0)),0,vlookup(B27,'Danh sách MASTER'!$B$3:$M$119,12,0)) -> 1 | J27: =vlookup(B27,'Danh sách MASTER'!$B$3:$V$118,21,0) -> Phú Anh
A28: =A27+1 -> 22 | B28: 076 | C28: Nguyễn Hoài Nam | D28: Vận hành | E28: Điều phối | F28: Công nhân bốc xếp | G28: Nam | H28: TWN2 | I28: =if(isna(vlookup(B28,'Danh sách MASTER'!$B$3:$M$119,12,0)),0,vlookup(B28,'Danh sách MASTER'!$B$3:$M$119,12,0)) -> 1 | J28: =vlookup(B28,'Danh sách MASTER'!$B$3:$V$118,21,0) -> Sơn Cảng
A29: =A28+1 -> 23 | B29: 081 | C29: Tăng Văn Tuấn | D29: Vận hành | E29: Điều phối | F29: Công nhân bốc xếp | G29: Nam | H29: TWN2 | I29: =if(isna(vlookup(B29,'Danh sách MASTER'!$B$3:$M$119,12,0)),0,vlookup(B29,'Danh sách MASTER'!$B$3:$M$119,12,0)) -> 1 | J29: =vlookup(B29,'Danh sách MASTER'!$B$3:$V$118,21,0) -> Sơn Cảng
A30: =A29+1 -> 24 | B30: 034 | C30: Hoàng Văn Võ | D30: Vận hành | E30: Điều phối | F30: Nhân viên Điều phối | G30: Nam | H30: TWN3 | I30: =if(isna(vlookup(B30,'Danh sách MASTER'!$B$3:$M$119,12,0)),0,vlookup(B30,'Danh sách MASTER'!$B$3:$M$119,12,0)) -> 1 | J30: =vlookup(B30,'Danh sách MASTER'!$B$3:$V$118,21,0) -> Phú Anh
A31: =A30+1 -> 25 | B31: 051 | C31: Hoàng Văn Kiên | D31: Vận hành | E31: Vận hành thiết bị | F31: Nhân viên vận hành thiết bị | G31: Nam | H31: TWN3 | I31: =if(isna(vlookup(B31,'Danh sách MASTER'!$B$3:$M$119,12,0)),0,vlookup(B31,'Danh sách MASTER'!$B$3:$M$119,12,0)) -> 1 | J31: =vlookup(B31,'Danh sách MASTER'!$B$3:$V$118,21,0) -> Phú Anh
A32: =A31+1 -> 26 | B32: 094 | C32: Luân Văn Mạnh | D32: Vận hành | E32: Điều phối | F32: Công nhân bốc xếp | G32: Nam | H32: TWN4 | I32: =if(isna(vlookup(B32,'Danh sách MASTER'!$B$3:$M$119,12,0)),0,vlookup(B32,'Danh sách MASTER'!$B$3:$M$119,12,0)) -> 1 | J32: =vlookup(B32,'Danh sách MASTER'!$B$3:$V$118,21,0) -> Sơn Cảng
A33: =A32+1 -> 27 | B33: 126 | C33: Lục Văn Quảng | D33: Vận hành | E33: Điều phối | F33: Công nhân bốc xếp | G33: Nam | H33: TWN4 | I33: =if(isna(vlookup(B33,'Danh sách MASTER'!$B$3:$M$119,12,0)),0,vlookup(B33,'Danh sách MASTER'!$B$3:$M$119,12,0)) -> 1 | J33: =vlookup(B33,'Danh sách MASTER'!$B$3:$V$118,21,0) -> Sơn Cảng
A34: =A33+1 -> 28 | B34: 030 | C34: Lương Văn Thành | D34: Vận hành | E34: Điều phối | F34: Nhân viên nghiệp vụ cổng cảng và kho bãi | G34: Nam | H34: TWN5 | I34: =if(isna(vlookup(B34,'Danh sách MASTER'!$B$3:$M$119,12,0)),0,vlookup(B34,'Danh sách MASTER'!$B$3:$M$119,12,0)) -> 1 | J34: =vlookup(B34,'Danh sách MASTER'!$B$3:$V$118,21,0) -> Phú Anh
A35: =A34+1 -> 29 | B35: 103 | C35: Đàm Văn Cương | D35: Vận tải | E35: Vận tải | F35: Chuyên viên điều phối vận tải | G35: Nam | H35: TWN5 | I35: =if(isna(vlookup(B35,'Danh sách MASTER'!$B$3:$M$119,12,0)),0,vlookup(B35,'Danh sách MASTER'!$B$3:$M$119,12,0)) -> 1 | J35: =vlookup(B35,'Danh sách MASTER'!$B$3:$V$118,21,0) -> Sơn Cảng
A36: =A35+1 -> 30 | B36: 131 | C36: Lâm Hữu Huy | D36: Vận hành | E36: Vận hành thiết bị | F36: Nhân viên vận hành thiết bị | G36: Nam | H36: TRP4 | I36: =if(isna(vlookup(B36,'Danh sách MASTER'!$B$3:$M$119,12,0)),0,vlookup(B36,'Danh sách MASTER'!$B$3:$M$119,12,0)) -> 1 | J36: =vlookup(B36,'Danh sách MASTER'!$B$3:$V$118,21,0) -> Sơn Cảng
A37: =A36+1 -> 31 | B37: 006 | C37: Trịnh Công Nguyên | D37: Vận hành | E37: Điều phối | F37: Trưởng bộ phận nghiệp vụ cổng cảng và kho bãi | G37: Nam | H37: TRP4 | I37: =if(isna(vlookup(B37,'Danh sách MASTER'!$B$3:$M$119,12,0)),0,vlookup(B37,'Danh sách MASTER'!$B$3:$M$119,12,0)) -> 1 | J37: =vlookup(B37,'Danh sách MASTER'!$B$3:$V$118,21,0) -> Phú Anh
A38: =A37+1 -> 32 | B38: 038 | C38: Hoàng Xuân Phúc | D38: Kinh doanh | E38: Phát triển thị trường | F38: Chuyên viên Kinh doanh | G38: Nam | H38: TRP4 | I38: 1 | J38: =vlookup(B38,'Danh sách MASTER'!$B$3:$V$118,21,0) -> Phú Anh
C39: TỔNG SỐ NGƯỜI | I39: =sum(I7:I38) -> 32
I40: =I39='Danh sách MASTER'!M119 -> TRUE | J40: check

Sheet Check list detail
A1: CHECKLIST CÔNG VIỆC TỔ CHỨC KỶ NIỆM 1 NĂM THƯƠNG HIỆU CÔNG TY - NGÀY 05-06/10/2026
A3: STT | B3: Nội dung công việc | C3: Thời gian hoàn thành | D3: Phụ trách | E3: Phối hợp | F3: HR team | G3: Công việc chính cần lưu ý | H3: Cập nhật Tiến độ
A4: I. CÔNG TÁC CHUẨN BỊ VÀ TRUYỀN THÔNG
A5: 1 | B5: Lên ý tưởng chương trình, sơ bộ agenda trình BOD phê duyệt | C5: 46279 | D5: HR | F5: Trang/Quyên
A6: 2 | B6: Truyền thông tới các đơn vị về chương trình và các nội dung mỗi đơn vị cần chuẩn bị | C6: 46280 | D6: HR | E6: Marketing | F6: Trang | G6: - Trang phục đi du lịch:Áo đồng phục công ty | H6: - Ánh đưa tin truyền thông trc sự kiện ngày 1/10, 4/10
A7: 3 | B7: - Thiết kế thư mời, backdrop , photobooth, biển chỉ dẫn, Hastag cầm tay, banner treo xe CB - QN - Thiết kế Led CMSN cty, CBNV, Led Game, Led văn nghệ, bốc thăm trúng thưởng | C7: 46288 | D7: MKT | E7: HR Quyên | F7: Ánh/Quyền | G7: - Dung: Lưu ý treo banner ở xe cùng Công đoàn - Gửi giấy mời cho CBNV & khách mời : 22/9 | H7: - Thư mời: 19/9 gửi lại version 1 - KHảo sát lại photobooth: 19/9 - Dỡ băng rôn mang theo hôm 6/9 để chụp ảnh
A8: 3.1 | B8: Standee đón khách tại sảnh tầng trệt, cạnh LED | C8: 46288 | D8: MKT | E8: HR Quyên | F8: Ánh/Quyền
A9: 4 | B9: Làm Video trình chiếu đầu chương trình | C9: 46292 | D9: MKT | E9: HR | F9: Ánh/Quyên | G9: - Lấy Hình ảnh/Video từ các BP - Tổng hợp và làm Video trình chiếu 10p | H9: - 21/9: Ánh gửi lại lịch bản V1
A10: 5 | B10: Phiếu bốc thăm CBNV, mượn bể cá/ thùng thuỷ tinh đựng phiếu | C10: 46287 | D10: HR | E10: MKT | F10: Trà/Ngân | G10: - Gửi giấy mời cho CBNV & khách mời : 22/9 - Ngân hỗ trợ phiếu bốc thăm trúng thưởng. Chuẩn bị hộp phiếu bốc thăm (Bình cá thuỷ tinh)
A11: 6 | B11: Chốt số lượng khách mời | C11: 46289 | D11: HR | E11: TGĐ | F11: Trang | G11: check với TGĐ gửi thư mời cho HĐQT/Greentech/ (Mởi Mrs. Hà, KT)\
A12: 7 | B12: Chuẩn bị bát phát biểu của CTHĐQT/TGĐ | C12: 46297 | D12: HR | E12: TGĐ
A13: 8 | B13: Viết MC script, Chuẩn bị nhạc nền cho các hạng mục: Đón khách, CEO lên phát biểu, Game, Bốc thăm trúng thưởng | C13: 46291 | D13: HR | E13: MKT, IT | F13: Quyên/Ánh/IT | H13: - CHeck nam MC hỗ trợ Ánh phần lead Game: Đức
B14: Chuẩn bị lì xì TLQM để trao quà sinh nhật cho nhân viên tháng 9 tháng 10 | D14: Quyên
A15: II. VĂN NGHỆ VÀ TRÒ CHƠI
A16: 1 | B16: Tiết mục văn nghệ | C16: 46280 | D16: HR | E16: MKT | F16: Quyên/Ánh/Thành | G16: Chốt các tiết mục biểu diễn vào 16/9 - VPHL: Lead team: Ms. Ánh - VPCB: lead team: Ms. Dung - Các đội tự chuẩn bị lead cho tiết mục văn nghệ & gửi IT | H16: - CHiều 19/9: Khảo sát sân khấu Thiên Anh
A17: 2 | B17: Lead game | C17: 46299 | D17: MKT | E17: HR | F17: Ánh | G17: Thiết kế game, chuẩn bị đạo cụ, phần thưởng Game, kịch bản game | H17: - Tâm gửi v1 của game
A18: 3 | B18: Thiết kế nội dung game | C18: 46283 | D18: MKT | E18: IT, HR | F18: Tâm/IT/Trà | G18: IT làm video các giải thưởng bốc thăm, ghép nhạc quay xổ số
A19: 4 | B19: Quản trò game | C19: 46299 | D19: MC | E19: HR | F19: Ánh/Huy/Trà
A20: 5 | B20: Bố trí Lễ tân đón khách và bưng hoa/quà, trao thưởng | C20: 46296 | D20: HR | E20: XNK | F20: Dung/Bằng Giang/Huy- Hằng KT | G20: Dung lead team, Trà chuẩn bị 2 bàn vuông, có khăn phủ đỏ (Hỏi khách sạn)
B21: Mua + bọc thùng quà 2 đội chơi
B22: In chữ "Giải Nhất/ Nhì/ Ba/ May mắn" lên giấy A4 và dán vào quà | C22: 46298 | E22: Team HLong
A24: III. HẬU CẦN
A25: 1 | B25: Chọn địa điểm tổ chức và đặt tiệc, đặt xe, book tour, đặt vé bảo tàng | C25: 7/9- 18/9 | D25: HR | E25: MH, KT | F25: Quyên/Dung/Hoàn/C. Hương | G25: - Bên MH: Làm hợp đồng & chốt giá Dịch vụ - Quyên: Phối hợp book tour thăm vịnh, khách sạn, vé bảo tàng, gửi danh sách phòng & gợi ý điểm check in cho CBNV khám phá vào chiều mùng 4/10 - Dung: Phối hợp MH đặt xe đưa đón đoàn CB - HL | H25: - Final thứ 2: Tàu, xe, khách sạn, nhà hàng Thiên Anh, nhà hàng ăn trưa tại khách sạn/NH Việt Nam. VP HL có ăn trưa cùng ngày 5/10 - Xin ý kiến về ctrinfh thăm bảo tàng buổi chiều có tiếp tục hay cắt để nghỉ ngơi: Trang chốt vào thứ 2
A26: 1.1 | B26: Mời HĐQT và check tham gia các chương trình | C26: 46287 | D26: HR
A27: 1.2 | B27: Mời khách Greentech (Huyền, a Hoàn, a Lê), Dũng Phát (a Dũng), CTV (c Mai, c Huệ), NV cũ (Hà) | C27: 46287 | D27: HR
A28: 1.3 | B28: Sắp xếp danh sách phòng nghỉ | D28: HR | F28: Dung, Hằng | G28: Lưu ý cập nhật nếu có người đổi phòng hoặc đổi danh sách tham gia
A29: 1.4 | B29: Kiểm danh sách ăn, danh sách món và nghiệm thu sau bữa trưa 5 & 6/10 | D29: HR
A30: =A25+1 -> 2 | B30: Chuẩn bị đồ uống/đồ ăn trên xe cho đoàn CB - HL Chuẩn bị đồ ăn sáng ngày 4/10 & đặt ăn tối ngày 5/10 | C30: 46298 | D30: HR | E30: Công đoàn | F30: Dung/Hằng/A Tùng | G30: - Ăn sáng 4/10: Mua bánh mỳ, giò, hoa quả, hạt hướng dương - Ăn tối: Liên hệ đặt ăn tối 5/10 - In danh sách đoàn, điểm danh, nhắc đoàn mang CCCD để check in khách sạn, lên tàu, mang áo công ty - Chuẩn bị thuốc say xe, túi bóng nôn đi đường, chuẩn bị y tế, thuốc cơ bản cho đoàn: Thuốc hạ sốt, giảm đau, urgo...
A31: =A26+1 -> 2.1 | B31: Nhận bánh kem | C31: 46300 | D31: HR | E31: Ánh Ngọc | G31: Nhận và bàn giao cho nhà hàng
A32: 3 | B32: Lên thực đơn buổi tiệc | C32: 46296 | D32: HR | E32: Sếp Thuỷ, Nhung, C. Thuận | F32: Trang | G32: - In biển tên bàn VIP - In menu thực đơn
A33: =A32+1 -> 4 | B33: Lên list đồ uống | C33: 46296 | D33: HR | E33: MH | F33: Quyên/Hoàn | G33: Kiểm tra còn rượu trắng hay ko Check có tính tiền đồ uống mang vào hay ko: Quyên
A34: =A33+1 -> 5 | B34: Tổng hợp danh sách CBCNV không tham gia | C34: 46297 | D34: Admin các BP | E34: HR | F34: Dung
A35: =A34+1 -> 6 | B35: Setup khu vực bàn để quà tặng, bốc thăm trúng thưởng | C35: 46299 | D35: HR | E35: nhà hàng | F35: Quyên | G35: Bàn vuông phủ vải đỏ, hỏi mượn vải phủ bên sự kiện, Sáng 4/10 check cty có bàn vuông hay ko | H35: Quyên check nhà hàng
A36: =A35+1 -> 7 | B36: Setup bàn tiệc, kiểm soát đồ ăn theo thực đơn | C36: 46299 | D36: HR | E36: nhà hàng | F36: C Thuận/Chị Nga | G36: Setup bàn VIP (có biển tên)- C Hương mượn biển Vip từ khách san
A37: =A36+1 -> 8 | B37: Setup âm thanh, ánh sáng, hiệu ứng | C37: 46299 | D37: IT | E37: Kỹ thuật bên Sự kiện | F37: Thành/Việt/Quyền | G37: check lại rọi đèn, check dc mượn mấy MIC
A38: =A37+1 -> 9 | B38: In phiếu bốc thăm, hộp đựng phiếu | C38: 46297 | D38: HR | E38: MH | F38: Ngân, Ngọc, Trà | G38: Chuẩn bị lọ thuỷ tinh đựng phiếu BTTT . Đóng dấu vào phiếu bốc thăm - Ngân
B39: Lấy mực khô, nướng, đập, bọc báo, cho vào túi | D39: HR | F39: Chị Nga bếp, chị Hoàn + 3 thanh niên CB hỗ trợ | G39: Cao Bằng cho 3 thanh niên hỗ trợ
A40: =A38+1 -> 10 | B40: Mượn bể cá thuỷ tinh đựng phiếu + Tag bàn VIP | C40: 46298 | D40: HR | F40: Trà | G40: Liên hệ chị Hương kế toán
A41: =A40+1 -> 11 | B41: Mua quà tặng tương ứng với các giải thưởng (chi tiết trong dự trù chi phí) | C41: 46291 | D41: MKT | E41: HR, IT, MH, KT | F41: Ánh/ Hoàn/Trà, Hằng | G41: - Ánh gửi ý tưởng các món quà truyền thông của MKT trước ngày 16/9 để lên order với MH - Quyên order các quà tặng với MH - Gói quà , Video quà tặng (Thành) | H41: - Check final quà tặng với sếp
A42: =A41+1 -> 12 | B42: Khay phục vụ trao thưởng (phủ vải đỏ) => vàng | C42: 46297 | D42: HR | E42: MH | F42: Trà | G42: Nhà hàng cho mượn 2 khay vuông 2 khay tròn phủ vải vàng
...

Sheet Checklist on air
B2: KỊCH BẢN ON-AIR & CHECKLIST ĐIỀU PHỐI GALA DINNER - KỶ NIỆM 1 NĂM THƯƠNG HIỆU
B3: Thời gian: 18:00 - 21:05 | Ngày: 06/10/2026 | Địa điểm: Trung tâm sự kiện Thăng Long
B4: TỔNG ĐIỀU PHỐI SÂN KHẤU | D4: MC CHƯƠNG TRÌNH | F4: KỸ THUẬT (ÂM THANH / LED) | H4: HẬU CẦN & LỄ TÂN SÂN KHẤU | I4: TIẾN ĐỘ ON-AIR
B5: Ms. Quyên / Ms. Trang (HR) | D5: Quyên Mr. Đức & Ms. Ánh (Lead game) | F5: Mr. Thành, Mr. Việt, Mr. Quyền (IT) | H5: Ms. Dung, Ms. Trà, Ms. Ngân, Mr. Huy | I5: =COUNTIF(#REF!, TRUE)&"/"&COUNTA(B11:B30)&" ("&TEXT(IF(COUNTA(B11:B30)>0, COUNTIF(#REF!, TRUE)/COUNTA(B11:B30), 0), "0%")&")" -> 0/17 (0%)
B8: STT | C8: Thời gian | D8: Phân cảnh / Nội dung kịch bản | E8: Kịch bản chi tiết & Lời dẫn MC (Script) | F8: Nhân sự thực hiện & Khách mời | G8: Kỹ thuật (Âm thanh - Ánh sáng - Màn hình LED) | H8: Hậu cần, Đạo cụ & Lễ tân sân khấu | I8: Ghi chú điều phối & Lưu ý khẩn cấp | J8: Nhà hàng
C9: Từ 13:30 | D9: Set up, vận chuyển đồ | E9: Vận chuyển: - Hàng bốc thăm may mắn: Ms. Hoàn phụ trách kiểm kê - Thanh niên hỗ trợ bê vác đồ: Huy + Vân Như kế toán - Rượu: Ms. Hoàn phụ trách - Mực khô: Chị Nga bếp nướng + 3 thanh niên hỗ trợ đập và xé mực | G9: Từ 15h00: - Chạy thử LED - Bật thử nhạc - Thử mic - Tập dượt văn nghệ từ 3h - Kiểm tra công tắc điện khu hội trường Thành PIC kỹ thuật | H9: - 2 bàn vuông phủ khăn đặt dưới sân khấu để toàn bộ quà - 1 bục phát biểu - 1 tháp bánh (để sẵn dưới sân khấu và sẽ bê lên trong chương trình) - 2 khay phủ vải để bưng quà - 1 bể cá thủy tinh đựng phiếu (Phiếu do Trà bảo quản trong phong bì niêm phong) - Chị Thuận + chị Hoàn: Kiểm tra số lượng chỗ ngồi + đồ uống + mực khô + ly uống rượu + chai rượu + menu đặt bàn + tag bàn VIP (Quyên confirm số lượng vào sáng ngày 5/10) | J9: - 2 bàn vuông để quà - 1 tháp bánh - 2 quả pháo điện đã set up
C10: 0.71875 | D10: Đoàn Cao Bằng tập trung tại sảnh Khách sạn để di chuyển ra nhà hàng | F10: - Trưởng, phó đoàn kiểm kê quân số (Mr. Nguyên + Mr. Trung) - Đoàn Hạ Long kiểm kê quân số (Ms. Trà)
B11: 1 | C11: 17:30 - 18:00 | D11: Đón khách, check-in, chụp ảnh Photobooth | E11: Đón tiếp Ban Lãnh đạo, CBNV và khách mời; hướng dẫn chụp ảnh photobooth, hướng dẫn khách vào bàn tiệc theo sơ đồ. Chụp ảnh tập thể ngay đầu chương trình | F11: Lễ tân (Ms. Dung lead, Bằng Giang, Huy, Hằng KT), Truyền thông (Ánh), Điều phối (Quyên) | G11: - Nhạc đón khách, gồm cả nhạc TLQM - Màn LED chính hiển thị visual chào mừng Gala 1 năm. - LED cửa đón sảnh 1600x160px chạy chữ chào mừng. | H11: Sắp xếp backdrop, photobooth, hashtag cầm tay, biển tên bàn VIP. Bình cá thủy tinh đựng phiếu bốc thăm.
C12: 0.74305556 | D12: Chuẩn bị vào tiệc | E12: MC thông báo khách vào ổn định chỗ ngồi MC kiểm tra xem VIP đã đến đủ chưa | F12: - Trưởng phó đoàn + trưởng phó phòng đôn đốc nhân viên vào vị trí ngồi - Dồn mâm | G12: Vẫn âm nhạc và LED như trên Chuẩn bị nhạc bài mở màn | H12: Đội văn nghệ vào vị trí | I12: Đội hậu cần kiểm tra bàn bánh kem có dao cắt bánh + bật lửa, nến cắm trên bánh - 1 khay có 10 ly bia ở cánh gà chuẩn bị cho nghi thức kỷ niệm. => Ms. Hoàn kiểm tra lại | J12: Bê bánh kem ra tháp bánh
C13: 0.75 | D13: Bắt đầu | E13: MC thông báo chương trình bắt đầu MC kiểm tra xem VIP đã đến đủ chưa để thông báo | G13: - Tắt đèn hội trường: Quyền điều phối kỹ thuật nhà hàng - Lên nhạc mở màn | J13: Tắt đèn hội trường
B14: 2 | C14: 18:00 - 18:05 | D14: Tiết mục văn nghệ mở màn Gala | E14: Múa mở màn | F14: Đội văn nghệ Hạ Long (Ms. Ánh lead), MC off-stage | G14: - Nhạc bài múa - LED backdrop
C15: 0.75416667 | E15: Múa xong | F15: Đội văn nghệ chào và xuống sân khấu | G15: - Đèn vẫn tắt - Nhạc dồn để MC lên sân khấu - Về LED chính chương trình
B16: 3 | C16: 18:06 - 18:15 | D16: Tuyên bố lý do, giới thiệu đại biểu | E16: MC bước ra chào mừng, tuyên bố lý do kỷ niệm 1 năm thương hiệu Tà Lùng Quang Minh. Trân trọng giới thiệu đại biểu HĐQT, BGĐ và đối tác khách mời. | F16: Quyên | G16: - Nhạc lên sau lời chào của MC - Nhạc giới thiệu đạo biểu khi MC xướng tên - Đèn follow rọi bàn VIP - Vẫn giữ LED chính - Chuẩn bị video 1 năm | H16: 2 Micro không dây chuẩn bị pin mới, kiểm tra tín hiệu tốt. Cầm sẵn bản danh sách đại biểu chuẩn xác chức danh.
B17: 4 | C17: 18:15 - 18:25 | D17: Trình chiếu video hành trình 1 năm | E17: MC dẫn dắt: "Kính mời quý vị cùng nhìn lại chặng đường 1 năm đầy tự hào vừa qua qua đoạn phim ngắn sau đây...". Trình chiếu clip | G17: Màn hình LED phát clip full HD.
B18: 5 | C18: 18:47 - 18:57 | D18: Phát biểu của đại diện Ban Lãnh đạo | E18: MC trân trọng kính mời Đại diện Ban Lãnh đạo (CTHĐQT / TGĐ) lên sân khấu chia sẻ cảm nghĩ, tri ân và nêu định hướng phát triển thương hiệu. | F18: Tổng Giám đốc | G18: - Nhạc chào mừng trang trọng khi Lãnh đạo bước lên sân khấu. - Bật đèn spotlight rọi bục phát biểu. - Màn LED chính - Quyền đưa mic cho sếp Định, cho 1 bật lửa vào túi quần | I18: Đội hậu cần kiểm tra bàn bánh kem có dao cắt bánh + bật lửa, nến cắm trên bánh, giấy ăn - 1 khay có 10 ly bia ở cánh gà chuẩn bị cho nghi thức kỷ niệm. => Ms. Hoàn kiểm tra lại
B19: 6 | C19: 18:57 - 19:05 | D19: Nghi thức kỷ niệm 1 năm: Thổi nến sinh nhật | E19: MC kính mời toàn thể Ban Lãnh đạo & HĐQT cùng lên sân khấu thực hiện nghi thức thổi nến | F19: Lãnh đạo | G19: - LED đếm ngược 5 >1 - Quyền bật lửa cho nến - Lãnh đạo tự thổi nến >> cắt bánh => Ms. Trang check sếp - 2 quả pháo điện bắn lên - Hội trường vỗ tay - Đèn bật sáng | H19: Đẩy bàn bánh sinh nhật (cắm nến và có bật lửa) ra giữa sân khấu; - Chuẩn bị giấy ăn | I19: Quyền châm nến và đẩy bàn bánh | J19: - Nhà hàng bê bàn tháp bánh ra giữa - Quyền điều phối nhà hàng bắn pháo điện
B20: 7 | C20: 19:05 - 19:10 | D20: Nâng ly khai tiệc | E20: Lễ tân dâng khay rượu rót sẵn trao cho BLĐ. MC bắt nhịp "1, 2, 3... Dzooo!", toàn thể hội trường nâng ly chúc mừng. | F20: - Lễ tân nhà hàng bê bia mời lãnh đạo | G20: - Nhạc nền nâng ly - Bật đèn hội trường | I20: Cử lễ tân thu dọn ly và đẩy bàn bánh vào cánh gà ngay sau khi nâng ly; báo nhà hàng bắt đầu lên món ăn tiệc. | J20: - Thu tháp bánh - Bật đèn hội trường
B21: 8 | C21: 19:10 - 19:40 | D21: Dùng tiệc tối Gala Dinner | E21: MC mời toàn thể CBNV và quan khách dùng tiệc ngon miệng, giao lưu thân mật giữa các phòng ban. Ban Lãnh đạo đi chúc rượu từng bàn. | F21: Khách dùng bữa | G21: - Bật playlist nhạc nền êm dịu, ấm cúng (acoustic/instrumental). - Màn LED chính | H21: Điều phối nhà hàng lên món đúng thực đơn đã duyệt (súp, hải sản, món nóng, tráng miệng). Kiểm tra tiếp đồ uống, rượu bia. | I21: MC và Ekip điều phối tranh thủ ăn nhẹ; kiểm tra sẵn sàng đạo cụ cho Game và Bốc thăm trúng thưởng phần 2.
B22: 9 | C22: 19:50 - 19:55 | D22: Văn nghệ mở màn Phần 2 (Hội) | E22: MC trở lại sân khấu khuấy động không khí, giới thiệu tiết mục văn nghệ đặc sắc mở màn phần 2 do Đội văn nghệ Cao Bằng biểu diễn. | F22: MC Ánh | G22: - Nhạc nhảy của đội Cao Bằng - LED theo bài | H22: Đạo cụ biểu diễn, trang phục biểu diễn Cao Bằng sẵn sàng; test 2 micro cầm tay cho ca sĩ/diễn viên. | I22: Nhắc đội văn nghệ Cao Bằng có mặt sẵn sàng ở cánh gà từ 19:45; kiểm tra danh sách sinh nhật CBNV.
B23: 10 | C23: 19:55 - 20:05 | D23: Chúc mừng sinh nhật CBNV tháng 9 & tháng 10 | E23: MC đọc tên trân trọng mời CBNV có sinh nhật trong tháng 9 & 10 lên sân khấu. Kính mời TGĐ lên trao quà, hoa và gửi lời chúc mừng tuổi mới. | F23: TGĐ trao quà, CBNV sinh nhật tháng 9 & 10, MC đọc tên Chủ tịch/ Phó tổng trao quà của TGĐ | G23: Bật nhạc sinh nhật vui tươi rộn ràng. Màn hình LED trình chiếu slide chúc mừng sinh nhật kèm danh sách và ảnh CBNV tháng 9 & 10. | H23: - Khay có lì xì - Lễ tân Hằng kế toán bê khay - Check xem có tặng hoa ko (check nếu có Ms. Trang phu nhân) | I23: Vẫn đọc full danh sách
B24: 11 | C24: 20:05 - 20:15 | D24: Trò chơi cá nhân sân khấu (Mini Game 1) | E24: Game Đuổi hình bắt chữ | F24: MC quản trò (Đức & Ánh), Thư ký game: Vân Lễ tân bê quà: Hằng/ Huy Người trao quà: Sếp Thủy | G24: Nhạc + LED game Trả lời xong loạt câu hỏi thì mời hết lên sân khấu trao quà | H24: - Quà: ô TLQM | I24: Sắp xếp vị trí sân khấu an toàn; lễ tân chuẩn bị bình cá thủy tinh đựng phiếu bốc thăm cho đợt 1.
B25: 12 | C25: 20:15 - 20:25 | D25: Bốc thăm may mắn - Đợt 1 (Giải May Mắn) | E25: MC phổ biến thể lệ bốc thăm. Kính mời đại diện Lãnh đạo lên bốc thăm các giải May Mắn. MC xướng số/tên người trúng giải lên nhận quà. | F25: MC Ánh trên sân khấu MC Đức khuấy động, mời khán giả bốc (có 12 giải thì mời 4 khách bốc 3 vé) Lễ tân Hằng bê bể cá có phiếu đi cùng Thư ký Vân + Như ghi chép kết quả 2 Phó Tổng trao | G25: Nhạc hồi hộp quay số (drum roll suspense), âm thanh chúc mừng chiến thắng vang dội khi công bố số trúng. Visual LED Bốc thăm. | H25: Bình cá thủy tinh đựng phiếu bốc thăm; khay phủ khăn vàng đựng quà các Giải May Mắn (quà bọc sẵn, dán nhãn giải). | I25: Kiểm tra tính hợp lệ của phiếu (dấu mộc, đúng tên, người trúng có mặt tại khán phòng); giữ lại phiếu đã trúng.
B26: 13 | C26: 20:25 - 20:35 | D26: Trò chơi tập thể sân khấu (Team Game) | E26: Game Tạo dáng theo hình | F26: MC Ánh + Đức, mời mỗi đội 5 người lên sân khấu Sếp Định trao giải | G26: Nhạc game vận động cực sung, nhịp điệu dồn dập. Đèn sân khấu chớp đổi màu liên tục theo nhịp trò chơi. | H26: Đạo cụ game đồng đội, 2 thùng quà lớn | I26: Đảm bảo khoảng trống sân khấu rộng rãi, nhắc nhở an toàn khi vận động; quản trò kiểm soát thời lượng đúng 10 phút.
B27: 14 | C27: 20:35 - 20:40 | D27: Tiết mục văn nghệ giao lưu kết nối | E27: Tiết mục nhảy của đoàn thanh niên Cao Bằng | F27: Đội văn nghệ biểu diễn, MC giới thiệu tiết mục | G27: LED + nhạc nhảy | H27: Mic, đạo cụ nhảy | I27: Khi trao giải Game thì đội nhảy đứng sẵn sàng dưới cánh gà
B28: 15 | C28: 20:40 - 20:55 | D28: Bốc thăm may mắn - Đợt 2 (Giải Ba, Nhì, Nhất) | E28: bốc thăm lần lượt: 10 Giải Ba -> 03 Giải Nhì -> 01 Giải Nhất. Phỏng vấn ngắn người trúng Giải Nhất. | F28: - Giải Ba: Mời nhân viên lên sân khấu bốc thăm > sếp Thủy trao - Giải Nhì: anh Tùng bốc, anh Tùng trao - Giải Nhất: sếp Định/ sếp Thắng - Thư ký Vân/ Như/ Ngân ghi chép kết quả | G28: Nhạc hồi hộp kịch tính đỉnh cao, tiếng trống dồn, hiệu ứng sting hoành tráng khi mở tên Giải Nhất. Visual LED vinh danh giải thưởng. | H28: Thùng phiếu bốc thăm, khay phủ khăn vàng, các gói quà Giải Ba, Giải Nhì, Giải Nhất đóng gói sang trọng, bảng giải thưởng. | I28: Xác minh phiếu trúng thưởng hợp lệ; chụp ảnh lưu niệm người trúng giải lớn cùng Lãnh đạo cấp cao.
B29: 17 | C29: 21:00 - 21:05 | D29: Tiết mục văn nghệ sôi động kết màn | E29: Đội văn nghệ Hạ Long lead bài hát tập thể sôi động (nhạc remix / flashmob), MC mời toàn thể Ban Lãnh đạo và CBNV cùng lên sân khấu hòa chung vũ điệu. | F29: Đội văn nghệ Hạ Long (sếp Thủy lead), Toàn thể CBNV công ty | G29: Nhạc + LED chính | H29: Thu dọn đạo cụ vào góc trong để mở rộng tối đa không gian sân khấu cho toàn bộ CBNV đứng biểu diễn. | I29: Khuấy động tinh thần đoàn kết, vui tươi; tập hợp đầy đủ các phòng ban lên sân khấu.
B30: 18 | C30: 21:05 - Kết thúc | D30: Chụp ảnh lưu niệm toàn thể công ty & Tiễn khách | E30: MC điều phối sắp xếp toàn thể CBNV và khách mời đứng vào khung hình sân khấu chụp ảnh kỷ niệm 1 năm. MC chào tạm biệt và dặn dò lịch trình ngày mai. | F30: MC điều phối, Thợ quay phim / chụp ảnh, Toàn thể CBNV | G30: Nhạc vui tươi, hân hoan. Đèn khán phòng bật sáng 100%. Màn LED hiển thị backdrop chụp ảnh kỷ niệm 1 năm thương hiệu. | H30: Ekip chụp ảnh chuẩn bị góc máy rộng lấy toàn cảnh. Đội lễ tân và hậu cần hỗ trợ kiểm tra đồ đạc, dọn dẹp đạo cụ và tiễn khách. | I30: Nhắc nhở CBNV kiểm tra tư trang cá nhân; nhắc giờ tập trung sáng 07/10 ra bến cảng đi tàu tham quan vịnh Hạ Long.
B31: TỔNG CỘNG | C31: 18:00 - 21:05 (185 phút) | D31: 18 phân cảnh điều phối chi tiết | E31: Đã chuẩn bị đầy đủ kịch bản, lời dẫn MC, hiệu ứng kỹ thuật và đạo cụ lễ tân | F31: Phối hợp đồng bộ toàn bộ các bộ phận (MC, IT, Hậu cần, Lễ tân, Văn nghệ) | G31: Kỹ thuật âm thanh, ánh sáng, màn hình LED túc trực 100% thời gian | H31: Đạo cụ, quà tặng, bánh kem, sâm panh tập kết đúng vị trí sau cánh gà | I31: Điều phối viên (Stage Manager) dùng bộ đàm kiểm soát nhịp On-Air liên tục

Sheet Sinh nhật
A1: DANH SÁCH NHÂN VIÊN CÓ SINH NHẬT THÁNG 9 & THÁNG 10/2026
A4: STT | B4: Mã nhân viên | C4: Họ và tên | D4: Phòng ban | E4: Bộ phận | F4: Vị trí | G4: Ngày sinh đầy đủ | H4: Ngày sinh | I4: Tháng sinh | J4: Ngày bắt đầu làm việc cho công ty | K4: Tham gia Gala
A5: 1 | B5: 066 | C5: Nguyễn Quang Đạt | D5: Kế hoạch - Dự án | E5: Ban Quản lý dự án | F5: Trưởng ban Quản lý dự án | G5: 32753 | H5: 2 | I5: 9 | J5: 46113 | K5: =IFNA(VLOOKUP(B5,'Danh sách MASTER'!$B$3:$P$119,15,0),0) -> 1
A6: =A5+1 -> 2 | B6: 028 | C6: Ngô Thị Nga | D6: Hành chính - Nhân sự | E6: Hành chính | F6: Nhân viên bếp | G6: 29841 | H6: 12 | I6: 9 | J6: 45964 | K6: =IFNA(VLOOKUP(B6,'Danh sách MASTER'!$B$3:$P$119,15,0),0) -> 1
A7: =A6+1 -> 3 | B7: 047 | C7: Nguyễn Thị Thu Hiền | D7: Kinh doanh | E7: Xuất nhập khẩu | F7: Nhân viên Thủ tục Xuất nhập khẩu | G7: 32768 | H7: 17 | I7: 9 | J7: 45962 | K7: =IFNA(VLOOKUP(B7,'Danh sách MASTER'!$B$3:$P$119,15,0),0)
A8: =A7+1 -> 4 | B8: 025 | C8: Bùi Hải Long | D8: Vận hành | E8: Điều phối | F8: Nhân viên Điều phối | G8: 36789 | H8: 20 | I8: 9 | J8: 45188 | K8: =IFNA(VLOOKUP(B8,'Danh sách MASTER'!$B$3:$P$119,15,0),0)
A9: =A8+1 -> 5 | B9: 016 | C9: Bế Ngọc Dung | D9: Hành chính - Nhân sự | E9: Hành chính - Nhân sự | F9: Nhân viên Hành chính - Nhân sự | G9: 35332 | H9: 24 | I9: 9 | J9: 45950 | K9: =IFNA(VLOOKUP(B9,'Danh sách MASTER'!$B$3:$P$119,15,0),0) -> 1
A10: =A9+1 -> 6 | B10: 109 | C10: Đặng Thị Minh Huyền | D10: Kinh doanh | E10: Xuất nhập khẩu | F10: Nhân viên Thủ tục Xuất nhập khẩu | G10: 37525 | H10: 26 | I10: 9 | J10: 46167 | K10: =IFNA(VLOOKUP(B10,'Danh sách MASTER'!$B$3:$P$119,15,0),0)
A11: =A10+1 -> 7 | B11: 141 | C11: Hoàng Văn Vinh | D11: Vận hành | E11: Điều phối | F11: Công nhân bốc xếp | G11: 29126 | H11: 28 | I11: 9 | J11: 46287 | K11: =IFNA(VLOOKUP(B11,'Danh sách MASTER'!$B$3:$P$119,15,0),0) -> 0
A12: =A11+1 -> 8 | B12: 026 | C12: Nguyễn Đức Anh | D12: Vận hành | E12: An ninh | F12: Nhân viên An ninh | G12: 35702 | H12: 29 | I12: 9 | J12: 45302 | K12: =IFNA(VLOOKUP(B12,'Danh sách MASTER'!$B$3:$P$119,15,0),0)
A13: =A12+1 -> 9 | B13: 095 | C13: Nguyễn Văn Bắc | D13: Vận hành | E13: Điều phối | F13: Công nhân bốc xếp | G13: 37904 | H13: 10 | I13: 10 | J13: 46150 | K13: =IFNA(VLOOKUP(B13,'Danh sách MASTER'!$B$3:$P$119,15,0),0)
